2024-04-22 15:39:41,379 - started running grid search for customer 36
2024-04-22 15:40:06,246 - started running grid search for customer 36
2024-04-22 15:58:30,953 - started running grid search for customer 36
2024-04-22 16:27:15,084 - started running grid search for customer 36
2024-04-22 16:27:17,367 - exception calling callback for <Future at 0x251dc0f2380 state=finished raised BrokenProcessPool>
joblib.externals.loky.process_executor._RemoteTraceback: 
"""
Traceback (most recent call last):
  File "C:\Users\Stijn\AppData\Local\Programs\Python\Python310\lib\site-packages\joblib\externals\loky\process_executor.py", line 391, in _process_worker
    call_item = call_queue.get(block=True, timeout=timeout)
  File "C:\Users\Stijn\AppData\Local\Programs\Python\Python310\lib\multiprocessing\queues.py", line 122, in get
    return _ForkingPickler.loads(res)
  File "C:\Users\Stijn\AppData\Local\Programs\Python\Python310\lib\site-packages\joblib\externals\cloudpickle\cloudpickle.py", line 649, in subimport
    __import__(name)
  File "C:\Users\Stijn\AppData\Local\Programs\Python\Python310\lib\site-packages\river\metrics\__init__.py", line 48, in <module>
    from .geometric_mean import GeometricMean
  File "C:\Users\Stijn\AppData\Local\Programs\Python\Python310\lib\site-packages\river\metrics\geometric_mean.py", line 4, in <module>
    from scipy import stats
  File "<frozen importlib._bootstrap>", line 1075, in _handle_fromlist
  File "C:\Users\Stijn\AppData\Local\Programs\Python\Python310\lib\site-packages\scipy\__init__.py", line 217, in __getattr__
    return _importlib.import_module(f'scipy.{name}')
  File "C:\Users\Stijn\AppData\Local\Programs\Python\Python310\lib\importlib\__init__.py", line 126, in import_module
    return _bootstrap._gcd_import(name[level:], package, level)
  File "C:\Users\Stijn\AppData\Local\Programs\Python\Python310\lib\site-packages\scipy\stats\__init__.py", line 485, in <module>
    from ._stats_py import *
  File "C:\Users\Stijn\AppData\Local\Programs\Python\Python310\lib\site-packages\scipy\stats\_stats_py.py", line 46, in <module>
    from . import distributions
  File "C:\Users\Stijn\AppData\Local\Programs\Python\Python310\lib\site-packages\scipy\stats\distributions.py", line 8, in <module>
    from ._distn_infrastructure import (rv_discrete, rv_continuous, rv_frozen)
  File "C:\Users\Stijn\AppData\Local\Programs\Python\Python310\lib\site-packages\scipy\stats\_distn_infrastructure.py", line 22, in <module>
    from scipy import optimize
  File "<frozen importlib._bootstrap>", line 1075, in _handle_fromlist
  File "C:\Users\Stijn\AppData\Local\Programs\Python\Python310\lib\site-packages\scipy\__init__.py", line 217, in __getattr__
    return _importlib.import_module(f'scipy.{name}')
  File "C:\Users\Stijn\AppData\Local\Programs\Python\Python310\lib\importlib\__init__.py", line 126, in import_module
    return _bootstrap._gcd_import(name[level:], package, level)
  File "C:\Users\Stijn\AppData\Local\Programs\Python\Python310\lib\site-packages\scipy\optimize\__init__.py", line 406, in <module>
    from ._root import *
  File "<frozen importlib._bootstrap>", line 1027, in _find_and_load
  File "<frozen importlib._bootstrap>", line 1006, in _find_and_load_unlocked
  File "<frozen importlib._bootstrap>", line 688, in _load_unlocked
  File "<frozen importlib._bootstrap_external>", line 879, in exec_module
  File "<frozen importlib._bootstrap_external>", line 975, in get_code
  File "<frozen importlib._bootstrap_external>", line 1074, in get_data
KeyboardInterrupt
"""

The above exception was the direct cause of the following exception:

Traceback (most recent call last):
  File "C:\Users\Stijn\AppData\Local\Programs\Python\Python310\lib\site-packages\joblib\externals\loky\_base.py", line 26, in _invoke_callbacks
    callback(self)
  File "C:\Users\Stijn\AppData\Local\Programs\Python\Python310\lib\site-packages\joblib\parallel.py", line 385, in __call__
    self.parallel.dispatch_next()
  File "C:\Users\Stijn\AppData\Local\Programs\Python\Python310\lib\site-packages\joblib\parallel.py", line 834, in dispatch_next
    if not self.dispatch_one_batch(self._original_iterator):
  File "C:\Users\Stijn\AppData\Local\Programs\Python\Python310\lib\site-packages\joblib\parallel.py", line 901, in dispatch_one_batch
    self._dispatch(tasks)
  File "C:\Users\Stijn\AppData\Local\Programs\Python\Python310\lib\site-packages\joblib\parallel.py", line 819, in _dispatch
    job = self._backend.apply_async(batch, callback=cb)
  File "C:\Users\Stijn\AppData\Local\Programs\Python\Python310\lib\site-packages\joblib\_parallel_backends.py", line 556, in apply_async
    future = self._workers.submit(SafeFunction(func))
  File "C:\Users\Stijn\AppData\Local\Programs\Python\Python310\lib\site-packages\joblib\externals\loky\reusable_executor.py", line 176, in submit
    return super().submit(fn, *args, **kwargs)
  File "C:\Users\Stijn\AppData\Local\Programs\Python\Python310\lib\site-packages\joblib\externals\loky\process_executor.py", line 1129, in submit
    raise self._flags.broken
joblib.externals.loky.process_executor.BrokenProcessPool: A task has failed to un-serialize. Please ensure that the arguments of the function are all picklable.
2024-04-22 16:27:20,613 - started running grid search for customer 36
2024-04-22 16:45:46,865 - Best neuron numbers: (3, 19)
2024-04-22 16:52:37,223 - started running grid search for customer 36
2024-04-22 17:54:40,849 - Best neuron numbers: (3, 22)
2024-04-22 18:01:14,275 - started running grid search for customer 36
2024-04-22 18:01:15,517 - exception calling callback for <Future at 0x18bee0fa4a0 state=finished raised TerminatedWorkerError>
Traceback (most recent call last):
  File "C:\Users\Stijn\AppData\Local\Programs\Python\Python310\lib\site-packages\joblib\externals\loky\_base.py", line 26, in _invoke_callbacks
    callback(self)
  File "C:\Users\Stijn\AppData\Local\Programs\Python\Python310\lib\site-packages\joblib\parallel.py", line 385, in __call__
    self.parallel.dispatch_next()
  File "C:\Users\Stijn\AppData\Local\Programs\Python\Python310\lib\site-packages\joblib\parallel.py", line 834, in dispatch_next
    if not self.dispatch_one_batch(self._original_iterator):
  File "C:\Users\Stijn\AppData\Local\Programs\Python\Python310\lib\site-packages\joblib\parallel.py", line 901, in dispatch_one_batch
    self._dispatch(tasks)
  File "C:\Users\Stijn\AppData\Local\Programs\Python\Python310\lib\site-packages\joblib\parallel.py", line 819, in _dispatch
    job = self._backend.apply_async(batch, callback=cb)
  File "C:\Users\Stijn\AppData\Local\Programs\Python\Python310\lib\site-packages\joblib\_parallel_backends.py", line 556, in apply_async
    future = self._workers.submit(SafeFunction(func))
  File "C:\Users\Stijn\AppData\Local\Programs\Python\Python310\lib\site-packages\joblib\externals\loky\reusable_executor.py", line 176, in submit
    return super().submit(fn, *args, **kwargs)
  File "C:\Users\Stijn\AppData\Local\Programs\Python\Python310\lib\site-packages\joblib\externals\loky\process_executor.py", line 1129, in submit
    raise self._flags.broken
joblib.externals.loky.process_executor.TerminatedWorkerError: A worker process managed by the executor was unexpectedly terminated. This could be caused by a segmentation fault while calling the function or by an excessive memory usage causing the Operating System to kill the worker.

2024-04-22 18:02:25,545 - started running grid search for customer 36
2024-04-22 18:03:06,711 - Best neuron numbers: (3, 3)
2024-04-22 18:03:28,499 - started running grid search for customer 36
2024-04-22 18:03:38,172 - started running grid search for customer 36
2024-04-22 18:04:14,238 - Best neuron numbers: (3, 3), best MAE: 0.04759358160885888
2024-04-22 18:05:30,405 - started running grid search for customer 36
2024-04-22 18:06:12,628 - Best neuron numbers: (3, 3), best MAE: 0.04759358160885888
2024-04-22 18:06:26,886 - started running grid search for customer 36
2024-04-22 18:07:03,118 - Best neuron numbers: (3, 3), best MAE: 0.03420798719706176
2024-04-22 18:08:43,048 - started running grid search for customer 36
2024-04-22 18:09:21,222 - Best neuron numbers: (3, 3), best MAE: 0.03420798719706176
2024-04-22 18:09:42,028 - started running grid search for customer 36
2024-04-22 18:10:18,564 - Best neuron numbers: (3, 3), best MAE: 0.03420798719706176
2024-04-22 18:11:05,509 - started running grid search for customer 36
2024-04-22 18:11:14,933 - started running grid search for customer 36
2024-04-22 18:11:29,973 - Best neuron numbers: (1, 1), best MAE: 0.11531557608578591
2024-04-22 18:12:09,974 - started running grid search for customer 36
2024-04-22 18:12:25,054 - Best neuron numbers: (1, 1), best MAE: 0.16903984495240243
2024-04-22 18:12:57,358 - started running grid search for customer 36
2024-04-22 18:27:40,203 - started running grid search for customer 36
2024-04-22 19:20:00,747 - started running grid search for customer 36
2024-04-22 19:20:04,458 - Starting training for neuron numbers: (1, 1)
2024-04-22 19:20:04,469 - Starting training for neuron numbers: (1, 2)
2024-04-22 19:20:04,482 - Starting training for neuron numbers: (1, 10)
2024-04-22 19:20:04,495 - Starting training for neuron numbers: (1, 3)
2024-04-22 19:20:04,526 - Starting training for neuron numbers: (1, 14)
2024-04-22 19:20:04,528 - Starting training for neuron numbers: (1, 5)
2024-04-22 19:20:04,639 - Starting training for neuron numbers: (1, 4)
2024-04-22 19:20:04,665 - Starting training for neuron numbers: (1, 6)
2024-04-22 19:20:04,769 - Starting training for neuron numbers: (1, 11)
2024-04-22 19:20:04,806 - Starting training for neuron numbers: (1, 13)
2024-04-22 19:20:04,977 - Starting training for neuron numbers: (1, 8)
2024-04-22 19:20:05,551 - Starting training for neuron numbers: (1, 9)
2024-04-22 19:20:05,807 - Starting training for neuron numbers: (1, 15)
2024-04-22 19:20:06,122 - Starting training for neuron numbers: (1, 12)
2024-04-22 19:20:08,141 - Starting training for neuron numbers: (1, 16)
2024-04-22 19:24:28,976 - started running grid search for customer 36
